<?xml version="1.0" ?>
<sdf version="1.8">
    <world name="Moving_robot">
        <physics name="1ms" type="ignored">
            <max_step_size>0.001</max_step_size>
            <real_time_factor>1.0</real_time_factor>
        </physics>
        <plugin
            filename="gz-sim-physics-system"
            name="gz::sim::systems::Physics">
        </plugin>
        <plugin
            filename="gz-sim-user-commands-system"
            name="gz::sim::systems::UserCommands">
        </plugin>
        <plugin
            filename="gz-sim-scene-broadcaster-system"
            name="gz::sim::systems::SceneBroadcaster">
        </plugin>
        <plugin
          filename="gz-sim-sensors-system"
          name="gz::sim::systems::Sensors">
          <render_engine>ogre2</render_engine>
        </plugin>

        <gui fullscreen="0">

              <!-- 3D scene -->
              <plugin filename="MinimalScene" name="3D View">
                <gz-gui>
                  <title>3D View</title>
                  <property type="bool" key="showTitleBar">false</property>
                  <property type="string" key="state">docked</property>
                </gz-gui>

                <engine>ogre2</engine>
                <scene>scene</scene>
                <ambient_light>1.0 1.0 1.0</ambient_light>
                <background_color>0.8 0.8 0.8</background_color>
                <camera_pose>-6 0 6 0 0.5 0</camera_pose>
              </plugin>

              <!-- Plugins that add functionality to the scene -->
              <plugin filename="EntityContextMenuPlugin" name="Entity context menu">
                <gz-gui>
                  <property key="state" type="string">floating</property>
                  <property key="width" type="double">5</property>
                  <property key="height" type="double">5</property>
                  <property key="showTitleBar" type="bool">false</property>
                </gz-gui>
              </plugin>
              <plugin filename="GzSceneManager" name="Scene Manager">
                <gz-gui>
                  <property key="resizable" type="bool">false</property>
                  <property key="width" type="double">5</property>
                  <property key="height" type="double">5</property>
                  <property key="state" type="string">floating</property>
                  <property key="showTitleBar" type="bool">false</property>
                </gz-gui>
              </plugin>
              <plugin filename="InteractiveViewControl" name="Interactive view control">
                <gz-gui>
                  <property key="resizable" type="bool">false</property>
                  <property key="width" type="double">5</property>
                  <property key="height" type="double">5</property>
                  <property key="state" type="string">floating</property>
                  <property key="showTitleBar" type="bool">false</property>
                </gz-gui>
              </plugin>
              <plugin filename="CameraTracking" name="Camera Tracking">
                <gz-gui>
                  <property key="resizable" type="bool">false</property>
                  <property key="width" type="double">5</property>
                  <property key="height" type="double">5</property>
                  <property key="state" type="string">floating</property>
                  <property key="showTitleBar" type="bool">false</property>
                </gz-gui>
              </plugin>
              <!-- World control -->
              <plugin filename="WorldControl" name="World control">
                <gz-gui>
                  <title>World control</title>
                  <property type="bool" key="showTitleBar">false</property>
                  <property type="bool" key="resizable">false</property>
                  <property type="double" key="height">72</property>
                  <property type="double" key="width">121</property>
                  <property type="double" key="z">1</property>

                  <property type="string" key="state">floating</property>
                  <anchors target="3D View">
                    <line own="left" target="left"/>
                    <line own="bottom" target="bottom"/>
                  </anchors>
                </gz-gui>

                <play_pause>true</play_pause>
                <step>true</step>
                <start_paused>true</start_paused>
                <use_event>true</use_event>

              </plugin>

              <!-- World statistics -->
              <plugin filename="WorldStats" name="World stats">
                <gz-gui>
                  <title>World stats</title>
                  <property type="bool" key="showTitleBar">false</property>
                  <property type="bool" key="resizable">false</property>
                  <property type="double" key="height">110</property>
                  <property type="double" key="width">290</property>
                  <property type="double" key="z">1</property>

                  <property type="string" key="state">floating</property>
                  <anchors target="3D View">
                    <line own="right" target="right"/>
                    <line own="bottom" target="bottom"/>
                  </anchors>
                </gz-gui>

                <sim_time>true</sim_time>
                <real_time>true</real_time>
                <real_time_factor>true</real_time_factor>
                <iterations>true</iterations>
              </plugin>

              <plugin filename="ImageDisplay" name="3D">
                <topic>boxes_3d_image</topic>
                <gz-gui>
                  <title>3D</title>
                  <property key="state" type="string">docked</property>
                  <property type="double" key="height">400</property>
                  <property type="double" key="width">600</property>
                </gz-gui>
              </plugin>

            </gui>

        <light type="directional" name="sun">
            <cast_shadows>true</cast_shadows>
            <pose>0 0 10 0 0 0</pose>
            <diffuse>0.8 0.8 0.8 1</diffuse>
            <specular>0.2 0.2 0.2 1</specular>
            <attenuation>
                <range>1000</range>
                <constant>0.9</constant>
                <linear>0.01</linear>
                <quadratic>0.001</quadratic>
            </attenuation>
            <direction>-0.5 0.1 -0.9</direction>
        </light>

        <model name="ground_plane">
            <static>true</static>
            <link name="link">
                <collision name="collision">
                <geometry>
                    <plane>
                    <normal>0 0 1</normal>
                    </plane>
                </geometry>
                </collision>
                <visual name="visual">
                <geometry>
                    <plane>
                    <normal>0 0 1</normal>
                    <size>100 100</size>
                    </plane>
                </geometry>
                <material>
                    <ambient>0.8 0.8 0.8 1</ambient>
                    <diffuse>0.8 0.8 0.8 1</diffuse>
                    <specular>0.8 0.8 0.8 1</specular>
                </material>
                </visual>
            </link>
        </model>

        <model name='vehicle_blue' canonical_link='chassis'>
            <pose relative_to='world'>-4 0 0 0 0 0</pose>   <!--the pose is relative to the world by default-->

            <link name='chassis'>
                <pose relative_to='__model__'>0.5 0 0.4 0 0 0</pose>
                <inertial> <!--inertial properties of the link mass, inertia matix-->
                    <mass>1.14395</mass>
                    <inertia>
                        <ixx>0.126164</ixx>
                        <ixy>0</ixy>
                        <ixz>0</ixz>
                        <iyy>0.416519</iyy>
                        <iyz>0</iyz>
                        <izz>0.481014</izz>
                    </inertia>
                </inertial>
                <visual name='visual'>
                    <geometry>
                        <box>
                            <size>2.0 1.0 0.5</size>
                        </box>
                    </geometry>
                    <!--let's add color to our link-->
                    <material>
                        <ambient>0.0 0.0 1.0 1</ambient>
                        <diffuse>0.0 0.0 1.0 1</diffuse>
                        <specular>0.0 0.0 1.0 1</specular>
                    </material>
                </visual>
                <collision name='collision'>
                    <geometry>
                        <box>
                            <size>2.0 1.0 0.5</size>
                        </box>
                    </geometry>
                </collision>
            </link>

            <!--let's build the left wheel-->
            <link name='left_wheel'>
                <pose relative_to="chassis">-0.5 0.6 0 -1.5707 0 0</pose> <!--angles are in radian-->
                <inertial>
                    <mass>2</mass>
                    <inertia>
                        <ixx>0.145833</ixx>
                        <ixy>0</ixy>
                        <ixz>0</ixz>
                        <iyy>0.145833</iyy>
                        <iyz>0</iyz>
                        <izz>0.125</izz>
                    </inertia>
                </inertial>
                <visual name='visual'>
                    <geometry>
                        <cylinder>
                            <radius>0.4</radius>
                            <length>0.2</length>
                        </cylinder>
                    </geometry>
                    <material>
                        <ambient>1.0 0.0 0.0 1</ambient>
                        <diffuse>1.0 0.0 0.0 1</diffuse>
                        <specular>1.0 0.0 0.0 1</specular>
                    </material>
                </visual>
                <collision name='collision'>
                    <geometry>
                        <cylinder>
                            <radius>0.4</radius>
                            <length>0.2</length>
                        </cylinder>
                    </geometry>
                </collision>
            </link>

            <!--copy and paste for right wheel but change position-->
            <link name='right_wheel'>
                <pose relative_to="chassis">-0.5 -0.6 0 -1.5707 0 0</pose> <!--angles are in radian-->
                <inertial>
                    <mass>1</mass>
                    <inertia>
                        <ixx>0.145833</ixx>
                        <ixy>0</ixy>
                        <ixz>0</ixz>
                        <iyy>0.145833</iyy>
                        <iyz>0</iyz>
                        <izz>0.125</izz>
                    </inertia>
                </inertial>
                <visual name='visual'>
                    <geometry>
                        <cylinder>
                            <radius>0.4</radius>
                            <length>0.2</length>
                        </cylinder>
                    </geometry>
                    <material>
                        <ambient>1.0 0.0 0.0 1</ambient>
                        <diffuse>1.0 0.0 0.0 1</diffuse>
                        <specular>1.0 0.0 0.0 1</specular>
                    </material>
                </visual>
                <collision name='collision'>
                    <geometry>
                        <cylinder>
                            <radius>0.4</radius>
                            <length>0.2</length>
                        </cylinder>
                    </geometry>
                </collision>
            </link>

            <frame name="caster_frame" attached_to='chassis'>
                <pose>0.8 0 -0.2 0 0 0</pose>
            </frame>

            <!--caster wheel-->
            <link name='caster'>
                <pose relative_to='caster_frame'/>
                <inertial>
                    <mass>1</mass>
                    <inertia>
                        <ixx>0.1</ixx>
                        <ixy>0</ixy>
                        <ixz>0</ixz>
                        <iyy>0.1</iyy>
                        <iyz>0</iyz>
                        <izz>0.1</izz>
                    </inertia>
                </inertial>
                <visual name='visual'>
                    <geometry>
                        <sphere>
                            <radius>0.2</radius>
                        </sphere>
                    </geometry>
                    <material>
                        <ambient>0.0 1 0.0 1</ambient>
                        <diffuse>0.0 1 0.0 1</diffuse>
                        <specular>0.0 1 0.0 1</specular>
                    </material>
                </visual>
                <collision name='collision'>
                    <geometry>
                        <sphere>
                            <radius>0.2</radius>
                        </sphere>
                    </geometry>
                </collision>
            </link>

             <link name="camera">
               <pose relative_to="chassis">1 0 0.5 0 0 0</pose>
               <inertial>
                 <mass>0.1</mass>
                 <inertia>
                   <ixx>0.000166667</ixx>
                   <iyy>0.000166667</iyy>
                   <izz>0.000166667</izz>
                 </inertia>
               </inertial>
               <collision name="collision">
                 <geometry>
                   <box>
                     <size>0.1 0.1 0.1</size>
                   </box>
                 </geometry>
               </collision>
               <visual name="visual">
                 <geometry>
                   <box>
                     <size>0.1 0.1 0.1</size>
                   </box>
                 </geometry>
               </visual>

                <sensor name="full_2d" type="boundingbox_camera">
                  <topic>boxes_full_2d</topic>
                  <camera>
                    <box_type>full_2d</box_type>
                    <horizontal_fov>1.57</horizontal_fov>
                    <image>
                      <width>800</width>
                      <height>600</height>
                    </image>
                    <clip>
                      <near>0.01</near>
                      <far>1000</far>
                    </clip>
                    <save enabled="true">
                      <path>bounding_box_full_2d_data</path>
                    </save>
                  </camera>
                  <always_on>1</always_on>
                  <update_rate>30</update_rate>
                  <visualize>true</visualize>
                </sensor>

                <sensor name="3d" type="boundingbox_camera">
                  <topic>boxes_3d</topic>
                  <camera>
                    <box_type>3d</box_type>
                    <horizontal_fov>1.57</horizontal_fov>
                    <image>
                      <width>800</width>
                      <height>600</height>
                    </image>
                    <clip>
                      <near>0.01</near>
                      <far>1000</far>
                    </clip>
                    <save enabled="true">
                      <path>bounding_box_3d_data</path>
                    </save>
                  </camera>
                  <always_on>1</always_on>
                  <update_rate>30</update_rate>
                  <visualize>true</visualize>
                </sensor>

                <sensor name='camera_depth' type='depth'>
                  <camera name='depth'>
                    <horizontal_fov>1.047</horizontal_fov>
                    <image>
                      <width>320</width>
                      <height>240</height>
                    </image>
                    <clip>
                      <near>0.01</near>
                      <far>1000</far>
                    </clip>
                  </camera>
                  <always_on>1</always_on>
                  <update_rate>30</update_rate>
                  <visualize>1</visualize>
                </sensor>
             </link>

            <!--connecting these links together using joints-->
            <joint name='left_wheel_joint' type='revolute'> <!--continous joint is not supported yet-->
                <pose relative_to='left_wheel'/>
                <parent>chassis</parent>
                <child>left_wheel</child>
                <axis>
                    <xyz expressed_in='__model__'>0 1 0</xyz> <!--can be defined as any frame or even arbitrary frames-->
                    <limit>
                        <lower>-1.79769e+308</lower>    <!--negative infinity-->
                        <upper>1.79769e+308</upper>     <!--positive infinity-->
                    </limit>
                </axis>
            </joint>

            <joint name='right_wheel_joint' type='revolute'>
                <pose relative_to='right_wheel'/>
                <parent>chassis</parent>
                <child>right_wheel</child>
                <axis>
                    <xyz expressed_in='__model__'>0 1 0</xyz>
                    <limit>
                        <lower>-1.79769e+308</lower>    <!--negative infinity-->
                        <upper>1.79769e+308</upper>     <!--positive infinity-->
                    </limit>
                </axis>
            </joint>

            <!--different type of joints ball joint--> <!--defult value is the child-->
            <joint name='caster_wheel' type='ball'>
                <parent>chassis</parent>
                <child>caster</child>
            </joint>

            <joint name='boundingbox_camera_joint' type='fixed'>
                <parent>chassis</parent>
                <child>camera</child>
            </joint>

            <!--diff drive plugin-->
            <plugin
                filename="libgz-sim-diff-drive-system.so"
                name="gz::sim::systems::DiffDrive">
                <left_joint>left_wheel_joint</left_joint>
                <right_joint>right_wheel_joint</right_joint>
                <wheel_separation>1.2</wheel_separation>
                <wheel_radius>0.4</wheel_radius>
                <odom_publish_frequency>1</odom_publish_frequency>
                <topic>cmd_vel</topic>
            </plugin>
        </model>

        <model name="box1">
              <pose>4 -3 0.5 0 0 0</pose>
              <link name="box_link">
                <inertial>
                  <inertia>
                    <ixx>1</ixx>
                    <ixy>0</ixy>
                    <ixz>0</ixz>
                    <iyy>1</iyy>
                    <iyz>0</iyz>
                    <izz>1</izz>
                  </inertia>
                  <mass>1.0</mass>
                </inertial>
                <collision name="box_collision">
                  <geometry>
                    <box>
                      <size>1 1 1</size>
                    </box>
                  </geometry>
                </collision>

                <visual name="box_visual">
                  <geometry>
                    <box>
                      <size>1 1 1</size>
                    </box>
                  </geometry>
                  <material>
                    <ambient>0 0 0.5 1</ambient>
                    <diffuse>0 0 1 1</diffuse>
                    <specular>0 0 0.3 1</specular>
                  </material>
                  <plugin filename="gz-sim-label-system" name="gz::sim::systems::Label">
                    <label>10</label>
                  </plugin>
                </visual>
              </link>
        </model>

        <model name="box2">
              <pose>4 0 0.5 0 0 0</pose>
              <link name="box_link">
                <inertial>
                  <inertia>
                    <ixx>1</ixx>
                    <ixy>0</ixy>
                    <ixz>0</ixz>
                    <iyy>1</iyy>
                    <iyz>0</iyz>
                    <izz>1</izz>
                  </inertia>
                  <mass>1.0</mass>
                </inertial>
                <collision name="box_collision">
                  <geometry>
                    <box>
                      <size>1 1 1</size>
                    </box>
                  </geometry>
                </collision>

                <visual name="box_visual">
                  <geometry>
                    <box>
                      <size>1 1 1</size>
                    </box>
                  </geometry>
                  <material>
                    <ambient>0 0 0.5 1</ambient>
                    <diffuse>0 0 1 1</diffuse>
                    <specular>0 0 0.3 1</specular>
                  </material>
                  <plugin filename="gz-sim-label-system" name="gz::sim::systems::Label">
                    <label>20</label>
                  </plugin>
                </visual>
              </link>
        </model>

        <model name="box3">
              <pose>4 3 0.5 0 0 0</pose>
              <link name="box_link">
                <inertial>
                  <inertia>
                    <ixx>1</ixx>
                    <ixy>0</ixy>
                    <ixz>0</ixz>
                    <iyy>1</iyy>
                    <iyz>0</iyz>
                    <izz>1</izz>
                  </inertia>
                  <mass>1.0</mass>
                </inertial>
                <collision name="box_collision">
                  <geometry>
                    <box>
                      <size>1 1 1</size>
                    </box>
                  </geometry>
                </collision>

                <visual name="box_visual">
                  <geometry>
                    <box>
                      <size>1 1 1</size>
                    </box>
                  </geometry>
                  <material>
                    <ambient>0 0 0.5 1</ambient>
                    <diffuse>0 0 1 1</diffuse>
                    <specular>0 0 0.3 1</specular>
                  </material>
                  <plugin filename="gz-sim-label-system" name="gz::sim::systems::Label">
                    <label>30</label>
                  </plugin>
                </visual>
              </link>
        </model>

        <actor name="actor_walking">
          <skin>
            <filename>https://fuel.gazebosim.org/1.0/Mingfei/models/actor/tip/files/meshes/walk.dae</filename>
            <scale>1.0</scale>
          </skin>
          <animation name='walk'>
            <filename>https://fuel.gazebosim.org/1.0/Mingfei/models/actor/tip/files/meshes/walk.dae</filename>
          </animation>
          <script>
            <loop>true</loop>
            <delay_start>0.000000</delay_start>
            <auto_start>true</auto_start>
            <trajectory id="0" type="walk">
              <waypoint>
                <time>0</time>
                <pose>2.0 4.0 1.0 0 0 0</pose>
              </waypoint>
              <waypoint>
                <time>2</time>
                <pose>2 1.0 1.0 0 0 0</pose>
              </waypoint>
            <waypoint>
                <time>4</time>
                <pose>2 4.0 1.0 0 0 0</pose>
              </waypoint>
            </trajectory>
          </script>
          <plugin filename="gz-sim-label-system" name="gz::sim::systems::Label">
            <label>40</label>
          </plugin>
        </actor>

        <!-- Moving Left-->
        <plugin filename="gz-sim-triggered-publisher-system"
                name="gz::sim::systems::TriggeredPublisher">
            <input type="gz.msgs.Int32" topic="/keyboard/keypress">
                <match field="data">16777234</match>
            </input>
            <output type="gz.msgs.Twist" topic="/cmd_vel">
                linear: {x: 0.0}, angular: {z: 0.5}
            </output>
        </plugin>
        <!-- Moving Forward-->
        <plugin filename="gz-sim-triggered-publisher-system"
                name="gz::sim::systems::TriggeredPublisher">
            <input type="gz.msgs.Int32" topic="/keyboard/keypress">
                <match field="data">16777235</match>
            </input>
            <output type="gz.msgs.Twist" topic="/cmd_vel">
                linear: {x: 0.5}, angular: {z: 0.0}
            </output>
        </plugin>
        <!-- Moving Right-->
        <plugin filename="gz-sim-triggered-publisher-system"
                name="gz::sim::systems::TriggeredPublisher">
            <input type="gz.msgs.Int32" topic="/keyboard/keypress">
                <match field="data">16777236</match>
            </input>
            <output type="gz.msgs.Twist" topic="/cmd_vel">
                linear: {x: 0.0}, angular: {z: -0.5}
            </output>
        </plugin>
        <!-- Moving Backward-->
        <plugin filename="gz-sim-triggered-publisher-system"
                name="gz::sim::systems::TriggeredPublisher">
            <input type="gz.msgs.Int32" topic="/keyboard/keypress">
                <match field="data">16777237</match>
            </input>
            <output type="gz.msgs.Twist" topic="/cmd_vel">
                linear: {x: -0.5}, angular: {z: 0.0}
            </output>
        </plugin>
    </world>
</sdf>